<?xml version="1.0" ?>
<!-- =================================================================================== -->
<!-- |    This document was autogenerated by xacro from /home/ericlab/ur_ws/src/ur_rikuken/arm_and_gripper/arm_and_gripper/urdf/ur3_85_realsense/ur3_85_realsense.urdf.xacro | -->
<!-- |    EDITING THIS FILE BY HAND IS NOT RECOMMENDED                                 | -->
<!-- =================================================================================== -->
<robot name="ur3e_gripper">
    <gazebo>
        <plugin filename="libgazebo_ros_control.so" name="ros_control" />
        <plugin filename="libgazebo_ros_p3d.so" name="ground_truth">
            <frameName>world</frameName>
            <bodyName>base_link</bodyName>
            <topicName>/tracker</topicName>
            <updateRate>10.0</updateRate>
        </plugin>
        <plugin name="gazebo_ros_control">
            <robotNamespace>/</robotNamespace>
        </plugin>
    </gazebo>
    <!--
  Author: Felix Messmer
-->
    <!-- measured from model -->
    <link name="base_link">
        <visual>
            <origin rpy="0 0 3.141592653589793" xyz="0 0 0" />
            <geometry>
                <mesh filename="package://arm_and_gripper/meshes/ur3e/visual/base.dae" />
            </geometry>
            <material name="LightGrey">
                <color rgba="0.7 0.7 0.7 1.0" />
            </material>
        </visual>
        <collision>
            <origin rpy="0 0 3.141592653589793" xyz="0 0 0" />
            <geometry>
                <mesh filename="package://arm_and_gripper/meshes/ur3e/visual/base.dae" />
            </geometry>
        </collision>
        <inertial>
            <mass value="2.0" />
            <origin rpy="0 0 0" xyz="0.0 0.0 0.0" />
            <inertia ixx="0.0030531654454" ixy="0.0" ixz="0.0" iyy="0.0030531654454" iyz="0.0" izz="0.005625" />
        </inertial>
    </link>
    <joint name="shoulder_pan_joint" type="revolute">
        <parent link="base_link" />
        <child link="shoulder_link" />
        <origin rpy="0 0 3.141592653589793" xyz="0 0 0.15185" />
        <axis xyz="0 0 1" />
        <limit effort="330.0" lower="-3.141592653589793" upper="3.141592653589793" velocity="3.14" />
        <dynamics damping="0.0" friction="0.0" />
    </joint>
    <link name="shoulder_link">
        <visual>
            <origin rpy="0 0 3.141592653589793" xyz="0 0 0" />
            <geometry>
                <mesh filename="package://arm_and_gripper/meshes/ur3e/visual/shoulder.dae" />
            </geometry>
            <material name="LightGrey">
                <color rgba="0.7 0.7 0.7 1.0" />
            </material>
        </visual>
        <collision>
            <origin rpy="0 0 3.141592653589793" xyz="0 0 0" />
            <geometry>
                <mesh filename="package://arm_and_gripper/meshes/ur3e/visual/shoulder.dae" />
            </geometry>
        </collision>
        <inertial>
            <mass value="2.0" />
            <origin rpy="0 0 0" xyz="0.0 0.0 0.0" />
            <inertia ixx="0.008093163429399999" ixy="0.0" ixz="0.0" iyy="0.008093163429399999" iyz="0.0" izz="0.005625" />
        </inertial>
    </link>
    <joint name="shoulder_lift_joint" type="revolute">
        <parent link="shoulder_link" />
        <child link="upper_arm_link" />
        <origin rpy="1.570796327 0 0" xyz="0 0 0" />
        <axis xyz="0 0 1" />
        <limit effort="330.0" lower="-3.141592653589793" upper="3.141592653589793" velocity="3.14" />
        <dynamics damping="0.0" friction="0.0" />
    </joint>
    <link name="upper_arm_link">
        <visual>
            <origin rpy="1.5707963267948966 0 -1.5707963267948966" xyz="0 0 0.12" />
            <geometry>
                <mesh filename="package://arm_and_gripper/meshes/ur3e/visual/upperarm.dae" />
            </geometry>
            <material name="LightGrey">
                <color rgba="0.7 0.7 0.7 1.0" />
            </material>
        </visual>
        <collision>
            <origin rpy="1.5707963267948966 0 -1.5707963267948966" xyz="0 0 0.12" />
            <geometry>
                <mesh filename="package://arm_and_gripper/meshes/ur3e/visual/upperarm.dae" />
            </geometry>
        </collision>
        <inertial>
            <mass value="3.42" />
            <origin rpy="0 1.5707963267948966 0" xyz="-0.121775 0.0 0.12" />
            <inertia ixx="0.021714598026657313" ixy="0.0" ixz="0.0" iyy="0.021714598026657313" iyz="0.0" izz="0.00961875" />
        </inertial>
    </link>
    <joint name="elbow_joint" type="revolute">
        <parent link="upper_arm_link" />
        <child link="forearm_link" />
        <origin rpy="0 0 0" xyz="-0.24355 0 0" />
        <axis xyz="0 0 1" />
        <limit effort="150.0" lower="-3.141592653589793" upper="3.141592653589793" velocity="3.14" />
        <dynamics damping="0.0" friction="0.0" />
    </joint>
    <link name="forearm_link">
        <visual>
            <origin rpy="1.5707963267948966 0 -1.5707963267948966" xyz="0 0 0.027" />
            <geometry>
                <mesh filename="package://arm_and_gripper/meshes/ur3e/visual/forearm.dae" />
            </geometry>
            <material name="LightGrey">
                <color rgba="0.7 0.7 0.7 1.0" />
            </material>
        </visual>
        <collision>
            <origin rpy="1.5707963267948966 0 -1.5707963267948966" xyz="0 0 0.027" />
            <geometry>
                <mesh filename="package://arm_and_gripper/meshes/ur3e/visual/forearm.dae" />
            </geometry>
        </collision>
        <inertial>
            <mass value="1.26" />
            <origin rpy="0 1.5707963267948966 0" xyz="-0.121775 0.0 0.027" />
            <inertia ixx="0.0065445675821719194" ixy="0.0" ixz="0.0" iyy="0.0065445675821719194" iyz="0.0" izz="0.00354375" />
        </inertial>
    </link>
    <joint name="wrist_1_joint" type="revolute">
        <parent link="forearm_link" />
        <child link="wrist_1_link" />
        <origin rpy="0 0 0" xyz="-0.2132 0 0.13105" />
        <axis xyz="0 0 1" />
        <limit effort="54.0" lower="-3.141592653589793" upper="3.141592653589793" velocity="6.28" />
        <dynamics damping="0.0" friction="0.0" />
    </joint>
    <link name="wrist_1_link">
        <visual>
            <origin rpy="1.5707963267948966 0 0" xyz="0 0 -0.104" />
            <geometry>
                <mesh filename="package://arm_and_gripper/meshes/ur3e/visual/wrist1.dae" />
            </geometry>
            <material name="LightGrey">
                <color rgba="0.7 0.7 0.7 1.0" />
            </material>
        </visual>
        <collision>
            <origin rpy="1.5707963267948966 0 0" xyz="0 0 -0.104" />
            <geometry>
                <mesh filename="package://arm_and_gripper/meshes/ur3e/visual/wrist1.dae" />
            </geometry>
        </collision>
        <inertial>
            <mass value="0.8" />
            <origin rpy="0 0 0" xyz="0.0 0.0 0.0" />
            <inertia ixx="0.0016106408557434" ixy="0.0" ixz="0.0" iyy="0.0016106408557434" iyz="0.0" izz="0.00225" />
        </inertial>
    </link>
    <joint name="wrist_2_joint" type="revolute">
        <parent link="wrist_1_link" />
        <child link="wrist_2_link" />
        <origin rpy="1.570796327 0 0" xyz="0 -0.08535 -1.750557762378351e-11" />
        <axis xyz="0 0 1" />
        <limit effort="54.0" lower="-3.141592653589793" upper="3.141592653589793" velocity="6.28" />
        <dynamics damping="0.0" friction="0.0" />
    </joint>
    <link name="wrist_2_link">
        <visual>
            <origin rpy="0 0 0" xyz="0 0 -0.08535" />
            <geometry>
                <mesh filename="package://arm_and_gripper/meshes/ur3e/visual/wrist2.dae" />
            </geometry>
            <material name="LightGrey">
                <color rgba="0.7 0.7 0.7 1.0" />
            </material>
        </visual>
        <collision>
            <origin rpy="0 0 0" xyz="0 0 -0.08535" />
            <geometry>
                <mesh filename="package://arm_and_gripper/meshes/ur3e/visual/wrist2.dae" />
            </geometry>
        </collision>
        <inertial>
            <mass value="0.8" />
            <origin rpy="0 0 0" xyz="0.0 0.0 0.0" />
            <inertia ixx="0.0016904933238023998" ixy="0.0" ixz="0.0" iyy="0.0016904933238023998" iyz="0.0" izz="0.00225" />
        </inertial>
    </link>
    <joint name="wrist_3_joint" type="revolute">
        <parent link="wrist_2_link" />
        <child link="wrist_3_link" />
        <origin rpy="1.570796326589793 3.141592653589793 3.141592653589793" xyz="0 0.0921 -1.8890025766262e-11" />
        <axis xyz="0 0 1" />
        <limit effort="54.0" lower="-3.141592653589793" upper="3.141592653589793" velocity="6.28" />
        <dynamics damping="0.0" friction="0.0" />
    </joint>
    <link name="wrist_3_link">
        <visual>
            <origin rpy="1.5707963267948966 0 0" xyz="0 0 -0.0921" />
            <geometry>
                <mesh filename="package://arm_and_gripper/meshes/ur3e/visual/wrist3.dae" />
            </geometry>
            <material name="LightGrey">
                <color rgba="0.7 0.7 0.7 1.0" />
            </material>
        </visual>
        <collision>
            <origin rpy="1.5707963267948966 0 0" xyz="0 0 -0.0921" />
            <geometry>
                <mesh filename="package://arm_and_gripper/meshes/ur3e/collision/wrist3.stl" />
            </geometry>
        </collision>
        <inertial>
            <mass value="0.35" />
            <origin rpy="0 0 0" xyz="0.0 0.0 -0.025" />
            <inertia ixx="0.000250104066625" ixy="0.0" ixz="0.0" iyy="0.000250104066625" iyz="0.0" izz="0.000354375" />
        </inertial>
    </link>
    <link name="realsense_coupling">
        <visual>
            <geometry>
                <mesh filename="package://arm_and_gripper/meshes/realsense_couplerv3.dae" />
            </geometry>
        </visual>
        <collision>
            <geometry>
                <mesh filename="package://arm_and_gripper/meshes/realsense_couplerv3.dae" />
            </geometry>
        </collision>
        <inertial>
            <mass value="0.05187" />
            <inertia ixx="1.442e+05" ixy="-0.03" ixz="0.008" iyy="22191.377" iyz="-3536.375" izz="1.656e+05" />
            <origin xyz="0 0 0" rpy="0 0 0" />
        </inertial>
    </link>
    <gazebo reference="realsense_coupling">
        <selfCollide>true</selfCollide>
    </gazebo>
    <joint name="realsense_coupling_joint" type="fixed">
        <origin rpy="1.5707963267948966 0.0 -1.5707963267948966" xyz="0.01 0.0 0.0" />
        <parent link="ee_link" />
        <child link="realsense_coupling" />
    </joint>
    <material name="camera_aluminum">
        <color rgba="0.5 0.5 0.5 1" />
    </material>
    <!-- camera body, with origin at bottom screw mount -->
    <joint name="camera_joint" type="fixed">
        <origin rpy="1.5707963267948966 1.5707963267948966 0.0" xyz="0.0001 0.1275 -0.001" />
        <parent link="realsense_coupling" />
        <child link="camera_bottom_screw_frame" />
    </joint>
    <link name="camera_bottom_screw_frame" />
    <joint name="camera_link_joint" type="fixed">
        <origin rpy="0 0 0" xyz="0 0.0175 0.0125" />
        <parent link="camera_bottom_screw_frame" />
        <child link="camera_link" />
    </joint>
    <link name="camera_link">
        <visual>
            <origin rpy="1.5707963267948966 0 1.5707963267948966" xyz="0.0149 -0.0175 0" />
            <geometry>
                <!-- <box size="${d435_cam_width} ${d435_cam_height} ${d435_cam_depth}"/> -->
                <mesh filename="package://realsense2_description/meshes/d435e.dae" />
            </geometry>
            <material name="camera_aluminum" />
        </visual>
        <collision>
            <origin rpy="0 0 0" xyz="0 -0.0175 0" />
            <geometry>
                <box size="0.02505 0.09 0.025" />
            </geometry>
        </collision>
        <inertial>
            <!-- The following are not reliable values, and should not be used for modeling -->
            <mass value="0.564" />
            <origin xyz="0 0 0" rpy="0 0 0" />
            <inertia ixx="0.003881243" ixy="0.0" ixz="0.0" iyy="0.000498940" iyz="0.0" izz="0.003879257" />
        </inertial>
    </link>
    <!-- camera depth joints and links -->
    <joint name="camera_depth_joint" type="fixed">
        <origin rpy="0 0 0" xyz="0 0 0" />
        <parent link="camera_link" />
        <child link="camera_depth_frame" />
    </joint>
    <link name="camera_depth_frame" />
    <joint name="camera_depth_optical_joint" type="fixed">
        <origin rpy="-1.5707963267948966 0 -1.5707963267948966" xyz="0 0 0" />
        <parent link="camera_depth_frame" />
        <child link="camera_depth_optical_frame" />
    </joint>
    <link name="camera_depth_optical_frame" />
    <!-- camera left IR joints and links -->
    <joint name="camera_left_ir_joint" type="fixed">
        <origin rpy="0 0 0" xyz="0 0.0 0" />
        <parent link="camera_depth_frame" />
        <child link="camera_left_ir_frame" />
    </joint>
    <link name="camera_left_ir_frame" />
    <joint name="camera_left_ir_optical_joint" type="fixed">
        <origin rpy="-1.5707963267948966 0 -1.5707963267948966" xyz="0 0 0" />
        <parent link="camera_left_ir_frame" />
        <child link="camera_left_ir_optical_frame" />
    </joint>
    <link name="camera_left_ir_optical_frame" />
    <!-- camera right IR joints and links -->
    <joint name="camera_right_ir_joint" type="fixed">
        <origin rpy="0 0 0" xyz="0 -0.05 0" />
        <parent link="camera_depth_frame" />
        <child link="camera_right_ir_frame" />
    </joint>
    <link name="camera_right_ir_frame" />
    <joint name="camera_right_ir_optical_joint" type="fixed">
        <origin rpy="-1.5707963267948966 0 -1.5707963267948966" xyz="0 0 0" />
        <parent link="camera_right_ir_frame" />
        <child link="camera_right_ir_optical_frame" />
    </joint>
    <link name="camera_right_ir_optical_frame" />
    <!-- camera color joints and links -->
    <joint name="camera_color_joint" type="fixed">
        <origin rpy="0 0 0" xyz="0 0.015 0" />
        <parent link="camera_depth_frame" />
        <child link="camera_color_frame" />
    </joint>
    <link name="camera_color_frame" />
    <joint name="camera_color_optical_joint" type="fixed">
        <origin rpy="-1.5707963267948966 0 -1.5707963267948966" xyz="0 0 0" />
        <parent link="camera_color_frame" />
        <child link="camera_color_optical_frame" />
    </joint>
    <link name="camera_color_optical_frame" />
    <gazebo reference="camera_link">
        <self_collide>0</self_collide>
        <enable_wind>0</enable_wind>
        <kinematic>0</kinematic>
        <gravity>1</gravity>
        <!--<mu>1</mu>-->
        <mu2>1</mu2>
        <fdir1>0 0 0</fdir1>
        <!--<slip1>0</slip1>
      <slip2>0</slip2>-->
        <kp>1e+13</kp>
        <kd>1</kd>
        <!--<max_vel>0.01</max_vel>
      <min_depth>0</min_depth>-->
        <sensor name="cameracolor" type="camera">
            <camera name="camera">
                <horizontal_fov>1.2112585008840648</horizontal_fov>
                <image>
                    <width>640</width>
                    <height>480</height>
                    <format>RGB_INT8</format>
                </image>
                <clip>
                    <near>0.1</near>
                    <far>100</far>
                </clip>
                <noise>
                    <type>gaussian</type>
                    <mean>0.0</mean>
                    <stddev>0.007</stddev>
                </noise>
            </camera>
            <always_on>1</always_on>
            <update_rate>30</update_rate>
            <visualize>1</visualize>
        </sensor>
        <sensor name="cameraired1" type="camera">
            <camera name="camera">
                <horizontal_fov>1.4870205226991688</horizontal_fov>
                <image>
                    <width>1280</width>
                    <height>720</height>
                    <format>L_INT8</format>
                </image>
                <clip>
                    <near>0.1</near>
                    <far>100</far>
                </clip>
                <noise>
                    <type>gaussian</type>
                    <mean>0.0</mean>
                    <stddev>0.05</stddev>
                </noise>
            </camera>
            <always_on>1</always_on>
            <update_rate>90</update_rate>
            <visualize>0</visualize>
        </sensor>
        <sensor name="cameraired2" type="camera">
            <camera name="camera">
                <horizontal_fov>1.4870205226991688</horizontal_fov>
                <image>
                    <width>1280</width>
                    <height>720</height>
                    <format>L_INT8</format>
                </image>
                <clip>
                    <near>0.1</near>
                    <far>100</far>
                </clip>
                <noise>
                    <type>gaussian</type>
                    <mean>0.0</mean>
                    <stddev>0.05</stddev>
                </noise>
            </camera>
            <always_on>1</always_on>
            <update_rate>90</update_rate>
            <visualize>0</visualize>
        </sensor>
        <sensor name="cameradepth" type="depth">
            <camera name="camera">
                <horizontal_fov>1.4870205226991688</horizontal_fov>
                <image>
                    <width>1280</width>
                    <height>720</height>
                </image>
                <clip>
                    <near>0.1</near>
                    <far>100</far>
                </clip>
                <noise>
                    <type>gaussian</type>
                    <mean>0.0</mean>
                    <stddev>0.100</stddev>
                </noise>
            </camera>
            <always_on>1</always_on>
            <update_rate>90</update_rate>
            <visualize>0</visualize>
        </sensor>
    </gazebo>
    <gazebo>
        <plugin filename="librealsense_gazebo_plugin.so" name="camera">
            <prefix>camera</prefix>
            <depthUpdateRate>30.0</depthUpdateRate>
            <colorUpdateRate>30.0</colorUpdateRate>
            <infraredUpdateRate>30.0</infraredUpdateRate>
            <depthTopicName>depth/image_raw</depthTopicName>
            <depthCameraInfoTopicName>depth/camera_info</depthCameraInfoTopicName>
            <colorTopicName>color/image_raw</colorTopicName>
            <colorCameraInfoTopicName>color/camera_info</colorCameraInfoTopicName>
            <infrared1TopicName>infra1/image_raw</infrared1TopicName>
            <infrared1CameraInfoTopicName>infra1/camera_info</infrared1CameraInfoTopicName>
            <infrared2TopicName>infra2/image_raw</infrared2TopicName>
            <infrared2CameraInfoTopicName>infra2/camera_info</infrared2CameraInfoTopicName>
            <colorOpticalframeName>camera_color_optical_frame</colorOpticalframeName>
            <depthOpticalframeName>camera_depth_optical_frame</depthOpticalframeName>
            <infrared1OpticalframeName>camera_left_ir_optical_frame</infrared1OpticalframeName>
            <infrared2OpticalframeName>camera_right_ir_optical_frame</infrared2OpticalframeName>
            <rangeMinDepth>0.2</rangeMinDepth>
            <rangeMaxDepth>10.0</rangeMaxDepth>
            <pointCloud>True</pointCloud>
            <pointCloudTopicName>depth/color/points</pointCloudTopicName>
            <pointCloudCutoff>0.25</pointCloudCutoff>
            <pointCloudCutoffMax>9.0</pointCloudCutoffMax>
        </plugin>
    </gazebo>
    <joint name="ee_fixed_joint" type="fixed">
        <parent link="wrist_3_link" />
        <child link="ee_link" />
        <origin rpy="0.0 -1.5707963267948966 1.5707963267948966" xyz="0.0 0.0 0.0" />
    </joint>
    <link name="ee_link">
        <collision>
            <geometry>
                <box size="0.01 0.01 0.01" />
            </geometry>
            <origin rpy="0 0 0" xyz="-0.01 0 0" />
        </collision>
        <inertial>
            <mass value="0.1" />
            <origin xyz="0 0 0" rpy="0 0 0" />
            <inertia ixx="0.03" iyy="0.03" izz="0.03" ixy="0.0" ixz="0.0" iyz="0.0" />
        </inertial>
    </link>
    <transmission name="shoulder_pan_trans">
        <type>transmission_interface/SimpleTransmission</type>
        <joint name="shoulder_pan_joint">
            <hardwareInterface>hardware_interface/PositionJointInterface</hardwareInterface>
        </joint>
        <actuator name="shoulder_pan_motor">
            <mechanicalReduction>1</mechanicalReduction>
            <hardwareInterface>hardware_interface/EffortJointInterface</hardwareInterface>
        </actuator>
    </transmission>
    <transmission name="shoulder_lift_trans">
        <type>transmission_interface/SimpleTransmission</type>
        <joint name="shoulder_lift_joint">
            <hardwareInterface>hardware_interface/PositionJointInterface</hardwareInterface>
        </joint>
        <actuator name="shoulder_lift_motor">
            <mechanicalReduction>1</mechanicalReduction>
            <hardwareInterface>hardware_interface/EffortJointInterface</hardwareInterface>
        </actuator>
    </transmission>
    <transmission name="elbow_trans">
        <type>transmission_interface/SimpleTransmission</type>
        <joint name="elbow_joint">
            <hardwareInterface>hardware_interface/PositionJointInterface</hardwareInterface>
        </joint>
        <actuator name="elbow_motor">
            <mechanicalReduction>1</mechanicalReduction>
            <hardwareInterface>hardware_interface/EffortJointInterface</hardwareInterface>
        </actuator>
    </transmission>
    <transmission name="wrist_1_trans">
        <type>transmission_interface/SimpleTransmission</type>
        <joint name="wrist_1_joint">
            <hardwareInterface>hardware_interface/PositionJointInterface</hardwareInterface>
        </joint>
        <actuator name="wrist_1_motor">
            <mechanicalReduction>1</mechanicalReduction>
            <hardwareInterface>hardware_interface/EffortJointInterface</hardwareInterface>
        </actuator>
    </transmission>
    <transmission name="wrist_2_trans">
        <type>transmission_interface/SimpleTransmission</type>
        <joint name="wrist_2_joint">
            <hardwareInterface>hardware_interface/PositionJointInterface</hardwareInterface>
        </joint>
        <actuator name="wrist_2_motor">
            <mechanicalReduction>1</mechanicalReduction>
            <hardwareInterface>hardware_interface/EffortJointInterface</hardwareInterface>
        </actuator>
    </transmission>
    <transmission name="wrist_3_trans">
        <type>transmission_interface/SimpleTransmission</type>
        <joint name="wrist_3_joint">
            <hardwareInterface>hardware_interface/PositionJointInterface</hardwareInterface>
        </joint>
        <actuator name="wrist_3_motor">
            <mechanicalReduction>1</mechanicalReduction>
            <hardwareInterface>hardware_interface/EffortJointInterface</hardwareInterface>
        </actuator>
    </transmission>
    <gazebo reference="shoulder_link">
        <selfCollide>true</selfCollide>
    </gazebo>
    <gazebo reference="upper_arm_link">
        <selfCollide>true</selfCollide>
    </gazebo>
    <gazebo reference="forearm_link">
        <selfCollide>true</selfCollide>
    </gazebo>
    <gazebo reference="wrist_1_link">
        <selfCollide>true</selfCollide>
    </gazebo>
    <gazebo reference="wrist_3_link">
        <selfCollide>true</selfCollide>
    </gazebo>
    <gazebo reference="wrist_2_link">
        <selfCollide>true</selfCollide>
    </gazebo>
    <gazebo reference="ee_link">
        <selfCollide>true</selfCollide>
    </gazebo>
    <!-- ROS base_link to UR 'Base' Coordinates transform -->
    <link name="base" />
    <joint name="base_link-base_fixed_joint" type="fixed">
        <!-- NOTE: this rotation is only needed as long as base_link itself is
                 not corrected wrt the real robot (ie: rotated over 180
                 degrees)
      -->
        <origin rpy="0 0 -3.141592653589793" xyz="0 0 0" />
        <parent link="base_link" />
        <child link="base" />
    </joint>
    <!-- Frame coincident with all-zeros TCP on UR controller -->
    <link name="tool0" />
    <joint name="wrist_3_link-tool0_fixed_joint" type="fixed">
        <origin rpy="0 0 0" xyz="0 0 0" />
        <parent link="wrist_3_link" />
        <child link="tool0" />
    </joint>
    <link name="world" />
    <link name="desk_link">
        <visual>
            <origin rpy="0.0 0.0 -1.5707963267948966" xyz="0.0 0.0 0.0" />
            <geometry>
                <mesh filename="package://arm_and_gripper/meshes/desk.dae" />
            </geometry>
        </visual>
        <collision>
            <origin rpy="0.0 0.0 -1.5707963267948966" xyz="0.0 0.0 0.0" />
            <geometry>
                <mesh filename="package://arm_and_gripper/meshes/desk.dae" />
            </geometry>
        </collision>
        <inertial>
            <mass value="13.887" />
            <inertia ixx="1.050e+09" ixy="0.001" ixz="-0.009" iyy="2.018e+09" iyz="3.428e+07" izz="1.795e+09" />
            <origin xyz="0 0 0" rpy="0 0 0" />
        </inertial>
    </link>
    <joint name="world_joint" type="fixed">
        <origin xyz="0.0 0.0 0.0" />
        <parent link="world" />
        <child link="desk_link" />
    </joint>
    <joint name="pedestal_joint" type="fixed">
        <origin xyz="0.15 0.0 0.7" />
        <parent link="desk_link" />
        <child link="base_link" />
    </joint>
    <!-- Robotiq Coupler -->
    <!--  + Height added by the coupler: 8mm -->
    <!--  + Reference frame: at the middle (4mm) -->
    <link name="robotiq_coupler">
        <visual>
            <geometry>
                <mesh filename="package://arm_and_gripper/meshes/robotiq_coupling.dae" />
            </geometry>
            <material name="flat_black" />
        </visual>
        <collision>
            <geometry>
                <mesh filename="package://arm_and_gripper/meshes/robotiq_coupling.dae" />
            </geometry>
        </collision>
        <inertial>
            <!--origin xyz="2.073e-05   1.45286e-03  -1.1049e-03" rpy="0 0 0" /-->
            <mass value="0.168" />
            <inertia ixx="6.69695624e-05" ixy="5.21511788e-09" ixz="-2.74383009e-08" iyy="7.85088161e-05" iyz="5.41105193e-07" izz="1.41819717e-04" />
            <origin xyz="0 0 0" rpy="0 0 0" />
        </inertial>
    </link>
    <joint name="robotiq_coupler_joint" type="fixed">
        <origin rpy="0 0 0" xyz="0 0 -0.007" />
        <parent link="realsense_coupling" />
        <child link="robotiq_coupler" />
    </joint>
    <gazebo reference="robotiq_coupler">
        <mu1>0.9</mu1>
        <mu2>0.9</mu2>
        <material>Gazebo/FlatBlack</material>
    </gazebo>
    <joint name="robotiq_85_base_joint" type="fixed">
        <parent link="robotiq_coupler" />
        <child link="robotiq_85_base_link" />
        <origin rpy="0.0 1.5707963267948966 1.5707963267948966" xyz="0 0 -0.004" />
    </joint>
    <link name="robotiq_85_base_link">
        <visual>
            <geometry>
                <mesh filename="package://arm_and_gripper/meshes/robotiq_85_gripper/visual/robotiq_85_base_link.dae" />
            </geometry>
        </visual>
        <collision>
            <geometry>
                <mesh filename="package://arm_and_gripper/meshes/robotiq_85_gripper/collision/robotiq_85_base_link.stl" />
            </geometry>
        </collision>
        <inertial>
            <mass value="0.636951" />
            <origin xyz="0.0 0.0 0.0" rpy="0 0 0" />
            <inertia ixx="0.000380" ixy="0.000000" ixz="0.000000" iyx="0.000000" iyy="0.001110" iyz="0.000000" izx="0.000000" izy="0.000000" izz="0.001171" />
        </inertial>
    </link>
    <joint name="robotiq_85_left_knuckle_joint" type="revolute">
        <parent link="robotiq_85_base_link" />
        <child link="robotiq_85_left_knuckle_link" />
        <axis xyz="0 0 1" />
        <origin rpy="3.141592653589793 0.0 0.0" xyz="0.05490451627 0.03060114443 0.0" />
        <limit effort="1000" lower="0.0" upper="0.80285" velocity="0.5" />
    </joint>
    <!-- <joint name="${prefix}robotiq_85_right_knuckle_joint" type="continuous"> -->
    <joint name="robotiq_85_right_knuckle_joint" type="revolute">
        <parent link="robotiq_85_base_link" />
        <child link="robotiq_85_right_knuckle_link" />
        <axis xyz="0 0 1" />
        <origin rpy="0.0 0.0 0.0" xyz="0.05490451627 -0.03060114443 0.0" />
        <limit effort="1000" lower="-3.14" upper="3.14" velocity="100.0" />
        <mimic joint="robotiq_85_left_knuckle_joint" />
    </joint>
    <link name="robotiq_85_left_knuckle_link">
        <visual>
            <geometry>
                <mesh filename="package://arm_and_gripper/meshes/robotiq_85_gripper/visual/robotiq_85_knuckle_link.dae" />
            </geometry>
        </visual>
        <collision>
            <geometry>
                <mesh filename="package://arm_and_gripper/meshes/robotiq_85_gripper/collision/robotiq_85_knuckle_link.stl" />
            </geometry>
        </collision>
        <inertial>
            <mass value="0.018491" />
            <origin xyz="0.0 0.0 0.0" rpy="0 0 0" />
            <inertia ixx="0.000009" ixy="-0.000001" ixz="0.000000" iyx="-0.000001" iyy="0.000001" iyz="0.000000" izx="0.000000" izy="0.000000" izz="0.000010" />
        </inertial>
    </link>
    <link name="robotiq_85_right_knuckle_link">
        <visual>
            <geometry>
                <mesh filename="package://arm_and_gripper/meshes/robotiq_85_gripper/visual/robotiq_85_knuckle_link.dae" />
            </geometry>
        </visual>
        <collision>
            <geometry>
                <mesh filename="package://arm_and_gripper/meshes/robotiq_85_gripper/collision/robotiq_85_knuckle_link.stl" />
            </geometry>
        </collision>
        <inertial>
            <mass value="0.018491" />
            <origin xyz="0.0 0.0 0.0" rpy="0 0 0" />
            <inertia ixx="0.000009" ixy="-0.000001" ixz="0.000000" iyx="-0.000001" iyy="0.000001" iyz="0.000000" izx="0.000000" izy="0.000000" izz="0.000010" />
        </inertial>
    </link>
    <joint name="robotiq_85_left_finger_joint" type="fixed">
        <parent link="robotiq_85_left_knuckle_link" />
        <child link="robotiq_85_left_finger_link" />
        <origin rpy="0 0 0" xyz="-0.00408552455 -0.03148604435 0.0" />
    </joint>
    <joint name="robotiq_85_right_finger_joint" type="fixed">
        <parent link="robotiq_85_right_knuckle_link" />
        <child link="robotiq_85_right_finger_link" />
        <origin rpy="0 0 0" xyz="-0.00408552455 -0.03148604435 0.0" />
    </joint>
    <link name="robotiq_85_left_finger_link">
        <visual>
            <geometry>
                <mesh filename="package://arm_and_gripper/meshes/robotiq_85_gripper/visual/robotiq_85_finger_link.dae" />
            </geometry>
        </visual>
        <collision>
            <geometry>
                <mesh filename="package://arm_and_gripper/meshes/robotiq_85_gripper/collision/robotiq_85_finger_link.stl" />
            </geometry>
        </collision>
        <inertial>
            <mass value="0.027309" />
            <origin xyz="0.0 0.0 0.0" rpy="0 0 0" />
            <inertia ixx="0.000003" ixy="-0.000002" ixz="0.000000" iyx="-0.000002" iyy="0.000021" iyz="0.000000" izx="0.000000" izy="0.000000" izz="0.000020" />
        </inertial>
    </link>
    <link name="robotiq_85_right_finger_link">
        <visual>
            <geometry>
                <mesh filename="package://arm_and_gripper/meshes/robotiq_85_gripper/visual/robotiq_85_finger_link.dae" />
            </geometry>
        </visual>
        <collision>
            <geometry>
                <mesh filename="package://arm_and_gripper/meshes/robotiq_85_gripper/collision/robotiq_85_finger_link.stl" />
            </geometry>
        </collision>
        <inertial>
            <mass value="0.027309" />
            <origin xyz="0.0 0.0 0.0" rpy="0 0 0" />
            <inertia ixx="0.000003" ixy="-0.000002" ixz="0.000000" iyx="-0.000002" iyy="0.000021" iyz="0.000000" izx="0.000000" izy="0.000000" izz="0.000020" />
        </inertial>
    </link>
    <!-- <joint name="${prefix}robotiq_85_left_inner_knuckle_joint" type="continuous"> -->
    <joint name="robotiq_85_left_inner_knuckle_joint" type="revolute">
        <parent link="robotiq_85_base_link" />
        <child link="robotiq_85_left_inner_knuckle_link" />
        <axis xyz="0 0 1" />
        <origin rpy="3.141592653589793 0.0 0.0" xyz="0.06142 0.0127 0" />
        <limit effort="0.1" lower="-3.14" upper="3.14" velocity="100.0" />
        <mimic joint="robotiq_85_left_knuckle_joint" offset="0" />
    </joint>
    <!-- <joint name="${prefix}robotiq_85_right_inner_knuckle_joint" type="continuous"> -->
    <joint name="robotiq_85_right_inner_knuckle_joint" type="revolute">
        <parent link="robotiq_85_base_link" />
        <child link="robotiq_85_right_inner_knuckle_link" />
        <axis xyz="0 0 1" />
        <origin rpy="0 0 0" xyz="0.06142 -0.0127 0" />
        <limit effort="0.1" lower="-3.14" upper="3.14" velocity="100.0" />
        <mimic joint="robotiq_85_left_knuckle_joint" offset="0" />
    </joint>
    <link name="robotiq_85_left_inner_knuckle_link">
        <visual>
            <geometry>
                <mesh filename="package://arm_and_gripper/meshes/robotiq_85_gripper/visual/robotiq_85_inner_knuckle_link.dae" />
            </geometry>
        </visual>
        <collision>
            <geometry>
                <mesh filename="package://arm_and_gripper/meshes/robotiq_85_gripper/collision/robotiq_85_inner_knuckle_link.stl" />
            </geometry>
        </collision>
        <inertial>
            <mass value="0.029951" />
            <origin xyz="0.0 0.0 0.0" rpy="0 0 0" />
            <inertia ixx="0.000039" ixy="0.000000" ixz="0.000000" iyx="0.000000" iyy="0.000005" iyz="0.000000" izx="0.000000" izy="0.000000" izz="0.000035" />
        </inertial>
    </link>
    <link name="robotiq_85_right_inner_knuckle_link">
        <visual>
            <geometry>
                <mesh filename="package://arm_and_gripper/meshes/robotiq_85_gripper/visual/robotiq_85_inner_knuckle_link.dae" />
            </geometry>
        </visual>
        <collision>
            <geometry>
                <mesh filename="package://arm_and_gripper/meshes/robotiq_85_gripper/collision/robotiq_85_inner_knuckle_link.stl" />
            </geometry>
        </collision>
        <inertial>
            <mass value="0.029951" />
            <origin xyz="0.0 0.0 0.0" rpy="0 0 0" />
            <inertia ixx="0.000039" ixy="0.000000" ixz="0.000000" iyx="0.000000" iyy="0.000005" iyz="0.000000" izx="0.000000" izy="0.000000" izz="0.000035" />
        </inertial>
    </link>
    <!-- <joint name="${prefix}robotiq_85_left_finger_tip_joint" type="continuous"> -->
    <joint name="robotiq_85_left_finger_tip_joint" type="revolute">
        <parent link="robotiq_85_left_inner_knuckle_link" />
        <child link="robotiq_85_left_finger_tip_link" />
        <axis xyz="0 0 1" />
        <origin rpy="0.0 0.0 0.0" xyz="0.04303959807 -0.03759940821 0.0" />
        <limit effort="0.1" lower="-3.14" upper="3.14" velocity="100.0" />
        <mimic joint="robotiq_85_left_knuckle_joint" multiplier="-1" />
    </joint>
    <!-- <joint name="${prefix}robotiq_85_right_finger_tip_joint" type="continuous"> -->
    <joint name="robotiq_85_right_finger_tip_joint" type="revolute">
        <parent link="robotiq_85_right_inner_knuckle_link" />
        <child link="robotiq_85_right_finger_tip_link" />
        <axis xyz="0 0 1" />
        <origin rpy="0.0 0.0 0.0" xyz="0.04303959807 -0.03759940821  0.0" />
        <limit effort="0.1" lower="-3.14" upper="3.14" velocity="100.0" />
        <mimic joint="robotiq_85_left_knuckle_joint" multiplier="-1" />
    </joint>
    <link name="robotiq_85_left_finger_tip_link">
        <visual>
            <geometry>
                <mesh filename="package://arm_and_gripper/meshes/robotiq_85_gripper/visual/robotiq_85_finger_tip_link.dae" />
            </geometry>
        </visual>
        <collision>
            <geometry>
                <mesh filename="package://arm_and_gripper/meshes/robotiq_85_gripper/collision/robotiq_85_finger_tip_link.stl" />
            </geometry>
        </collision>
        <inertial>
            <mass value="0.019555" />
            <origin xyz="0.0 0.0 0.0" rpy="0 0 0" />
            <inertia ixx="0.000002" ixy="0.000000" ixz="0.000000" iyx="0.000000" iyy="0.000005" iyz="0.000000" izx="0.000000" izy="0.000000" izz="0.000006" />
        </inertial>
    </link>
    <link name="robotiq_85_right_finger_tip_link">
        <visual>
            <geometry>
                <mesh filename="package://arm_and_gripper/meshes/robotiq_85_gripper/visual/robotiq_85_finger_tip_link.dae" />
            </geometry>
        </visual>
        <collision>
            <geometry>
                <mesh filename="package://arm_and_gripper/meshes/robotiq_85_gripper/collision/robotiq_85_finger_tip_link.stl" />
            </geometry>
        </collision>
        <inertial>
            <mass value="0.019555" />
            <origin xyz="0.0 0.0 0.0" rpy="0 0 0" />
            <inertia ixx="0.000002" ixy="0.000000" ixz="0.000000" iyx="0.000000" iyy="0.000005" iyz="0.000000" izx="0.000000" izy="0.000000" izz="0.000006" />
        </inertial>
    </link>
    <!-- Improve grasping physics -->
    <gazebo reference="robotiq_85_left_finger_tip_link">
        <kp>1000000.0</kp>
        <kd>1.0</kd>
        <mu1>1.5</mu1>
        <mu2>1.5</mu2>
        <minDepth>0.00</minDepth>
    </gazebo>
    <gazebo reference="robotiq_85_right_finger_tip_link">
        <kp>1000000.0</kp>
        <kd>1.0</kd>
        <mu1>1.5</mu1>
        <mu2>1.5</mu2>
        <minDepth>0.00</minDepth>
    </gazebo>
    <transmission name="robotiq_85_left_knuckle_trans">
        <type>transmission_interface/SimpleTransmission</type>
        <joint name="robotiq_85_left_knuckle_joint">
            <hardwareInterface>PositionJointInterface</hardwareInterface>
            <!-- <hardwareInterface>EffortJointInterface</hardwareInterface> -->
        </joint>
        <actuator name="robotiq_85_left_knuckle_motor">
            <mechanicalReduction>1</mechanicalReduction>
            <hardwareInterface>PositionJointInterface</hardwareInterface>
            <!-- <hardwareInterface>EfforJointInterface</hardwareInterface> -->
        </actuator>
    </transmission>
    <!-- Mimic joints -->
    <gazebo>
        <plugin filename="libroboticsgroup_upatras_gazebo_mimic_joint_plugin.so" name="mimic_robotiq_85_1">
            <joint>robotiq_85_left_knuckle_joint</joint>
            <mimicJoint>robotiq_85_right_knuckle_joint</mimicJoint>
        </plugin>
        <plugin filename="libroboticsgroup_upatras_gazebo_mimic_joint_plugin.so" name="mimic_robotiq_85_2">
            <joint>robotiq_85_left_knuckle_joint</joint>
            <mimicJoint>robotiq_85_left_inner_knuckle_joint</mimicJoint>
        </plugin>
        <plugin filename="libroboticsgroup_upatras_gazebo_mimic_joint_plugin.so" name="mimic_robotiq_85_3">
            <joint>robotiq_85_left_knuckle_joint</joint>
            <mimicJoint>robotiq_85_right_inner_knuckle_joint</mimicJoint>
        </plugin>
        <plugin filename="libroboticsgroup_upatras_gazebo_mimic_joint_plugin.so" name="mimic_robotiq_85_4">
            <joint>robotiq_85_left_knuckle_joint</joint>
            <mimicJoint>robotiq_85_left_finger_tip_joint</mimicJoint>
            <multiplier>-1.0</multiplier>
            <offset>0.0</offset>
        </plugin>
        <plugin filename="libroboticsgroup_upatras_gazebo_mimic_joint_plugin.so" name="mimic_robotiq_85_5">
            <joint>robotiq_85_left_knuckle_joint</joint>
            <mimicJoint>robotiq_85_right_finger_tip_joint</mimicJoint>
            <multiplier>-1.0</multiplier>
            <offset>0.0</offset>
        </plugin>
    </gazebo>
    <!-- Gazebo FT sensor plugin -->
    <gazebo reference="wrist_3_joint">
        <provideFeedback>true</provideFeedback>
    </gazebo>
    <!-- <joint name="end_end_joint" type="fixed">
    <origin xyz="0.0 0.0 -0.004" rpy="0.0 ${pi/2} ${pi/2}"/>
    <parent link="robotiq_coupler"/>
    <child link="robotiq_85_base_link"/>
    <axis xyz="0.0 0.0 0.0"/>
  </joint> -->
    <transmission name="trans_robotiq_85_right_knuckle_joint">
        <type>transmission_interface/SimpleTransmission</type>
        <joint name="robotiq_85_right_knuckle_joint">
            <hardwareInterface>hardware_interface/EffortJointInterface</hardwareInterface>
        </joint>
        <actuator name="robotiq_85_right_knuckle_joint_motor">
            <hardwareInterface>hardware_interface/EffortJointInterface</hardwareInterface>
            <mechanicalReduction>1</mechanicalReduction>
        </actuator>
    </transmission>
    <transmission name="trans_robotiq_85_left_inner_knuckle_joint">
        <type>transmission_interface/SimpleTransmission</type>
        <joint name="robotiq_85_left_inner_knuckle_joint">
            <hardwareInterface>hardware_interface/EffortJointInterface</hardwareInterface>
        </joint>
        <actuator name="robotiq_85_left_inner_knuckle_joint_motor">
            <hardwareInterface>hardware_interface/EffortJointInterface</hardwareInterface>
            <mechanicalReduction>1</mechanicalReduction>
        </actuator>
    </transmission>
    <transmission name="trans_robotiq_85_right_inner_knuckle_joint">
        <type>transmission_interface/SimpleTransmission</type>
        <joint name="robotiq_85_right_inner_knuckle_joint">
            <hardwareInterface>hardware_interface/EffortJointInterface</hardwareInterface>
        </joint>
        <actuator name="robotiq_85_right_inner_knuckle_joint_motor">
            <hardwareInterface>hardware_interface/EffortJointInterface</hardwareInterface>
            <mechanicalReduction>1</mechanicalReduction>
        </actuator>
    </transmission>
    <transmission name="trans_robotiq_85_left_finger_tip_joint">
        <type>transmission_interface/SimpleTransmission</type>
        <joint name="robotiq_85_left_finger_tip_joint">
            <hardwareInterface>hardware_interface/EffortJointInterface</hardwareInterface>
        </joint>
        <actuator name="robotiq_85_left_finger_tip_joint_motor">
            <hardwareInterface>hardware_interface/EffortJointInterface</hardwareInterface>
            <mechanicalReduction>1</mechanicalReduction>
        </actuator>
    </transmission>
    <transmission name="trans_robotiq_85_right_finger_tip_joint">
        <type>transmission_interface/SimpleTransmission</type>
        <joint name="robotiq_85_right_finger_tip_joint">
            <hardwareInterface>hardware_interface/EffortJointInterface</hardwareInterface>
        </joint>
        <actuator name="robotiq_85_right_finger_tip_joint_motor">
            <hardwareInterface>hardware_interface/EffortJointInterface</hardwareInterface>
            <mechanicalReduction>1</mechanicalReduction>
        </actuator>
    </transmission>
</robot>

